Workbook

Sheet Datos
P1: DILIGENCIAMIENTO DEL TECNICO
A2: 1 | B2: 2 | C2: 3 | D2: 4 | E2: 5 | F2: 6 | G2: 7 | H2: 8 | I2: 9 | J2: 10 | K2: 11 | L2: 12 | M2: 13 | N2: 14 | O2: 15 | P2: 16 | Q2: 17 | T2: 18 | U2: 19 | V2: 20 | W2: 21 | X2: 22 | Y2: 23 | Z2: 24 | AA2: 25
A3: CONSECUTIVO | B3: Nombre1 | C3: Documento de Identidad | D3: TIPO DE MANTENIMIENTO | E3: Fecha del reporte | F3: Hora de ingreso | G3: Nombre del Equipo | H3: Marca | I3: Placa del equipo | J3: Número INTERNO | K3: Laboratorio de ubicación | L3: Asignatura | M3: Número de banco | N3: Descripción del daño | O3: observacion | P3: Técnico | Q3: FECHA DE REALIZACIÓN | R3: DATOS EMPRESA CONTRATADA | S3: TIEMPO DE GARANTÍA | T3: Diagnóstico | U3: ESPECIFICACIONES DEL MANTENIMIENTO REALIZADO | V3: ESTADO | W3: RESPUESTO SOLICITADO | X3: Link del repuesto | Y3: Estado solicitud | Z3: Celular | AA3: Tipo solicitante
A4: S-01 | B4: Juan Camilo Cañas | C4: 1005205581 | D4: MIP | E4: 46088 | F4: 0.41666667 | G4: fuentes DC | H4: PEAC | I4: 2017090000000 | K4: Electrónica A 603 | L4: NA | N4: Se realizará MIP de limpieza interna y externa del equipo, de acuerdo con los tiempos establecidos en el cronograma de mantenimiento. Esta intervención se lleva a cabo con el fin de prevenir fallas asociadas a la acumulación de polvo, suciedad y posibles falsos contactos, los cuales pueden afectar el desempeño, la seguridad y la vida útil del equipo. | P4: Juan Camilo Cañas | Q4: 46088 | R4: Contratistas laboratorios de IEE | S4: N.A | T4: Durante la inspección se evidenció exceso de polvo y suciedad acumulada en el ventilador y en la placa del equipo, lo cual puede afectar la correcta disipación de calor y el funcionamiento adecuado de los componentes electrónicos. | U4: Como parte del mantenimiento, se realizó limpieza externa e interna del equipo, incluyendo la limpieza de las placas de circuito con limpiacontactos. Asimismo, se efectuó la limpieza de bornes, conectores, panel frontal y pantallas. Adicionalmente, se llevó a cabo la revisión y ajuste de perillas de control, inspección del cable de alimentación, verificación de interruptores y evaluación del sistema de ventilación, garantizando el correcto funcionamiento del equipo. | V4: Operativo | Y4: Finalizada | AA4: Tecnico
A5: S-02 | B5: Juan Camilo Cañas | C5: 1005205581 | D5: MIP | E5: 46088 | F5: 0.45833333 | G5: fuentes DC | H5: PEAKTECH | I5: 410324 | J5: EA15 | K5: Electrónica A 603 | L5: NA | N5: Se realizará MIP de limpieza interna y externa del equipo, de acuerdo con los tiempos establecidos en el cronograma de mantenimiento. Esta intervención se lleva a cabo con el fin de prevenir fallas asociadas a la acumulación de polvo, suciedad y posibles falsos contactos, los cuales pueden afectar el desempeño, la seguridad y la vida útil del equipo. | P5: Juan Camilo Cañas | Q5: 46088 | R5: Contratistas laboratorios de IEE | S5: N.A | T5: Durante la inspección se evidenció exceso de polvo y suciedad acumulada en el ventilador y en la placa del equipo, lo cual puede afectar la correcta disipación de calor y el funcionamiento adecuado de los componentes electrónicos. | U5: Como parte del mantenimiento, se realizó limpieza externa e interna del equipo, incluyendo la limpieza de las placas de circuito con limpiacontactos. Asimismo, se efectuó la limpieza de bornes, conectores, panel frontal y pantallas. Adicionalmente, se llevó a cabo la revisión y ajuste de perillas de control, inspección del cable de alimentación, verificación de interruptores y evaluación del sistema de ventilación, garantizando el correcto funcionamiento del equipo. | V5: Operativo | Y5: Finalizada | AA5: Tecnico
A6: S-03 | B6: Juan Camilo Cañas | C6: 1005205581 | D6: MIP | E6: 46088 | F6: 0.5 | G6: fuentes DC | H6: PEAKTECH | I6: 410316 | K6: Electrónica A 603 | L6: NA | N6: Se realizará MIP de limpieza interna y externa del equipo, de acuerdo con los tiempos establecidos en el cronograma de mantenimiento. Esta intervención se lleva a cabo con el fin de prevenir fallas asociadas a la acumulación de polvo, suciedad y posibles falsos contactos, los cuales pueden afectar el desempeño, la seguridad y la vida útil del equipo. | P6: Juan Camilo Cañas | Q6: 46088 | R6: Contratistas laboratorios de IEE | S6: N.A | T6: Durante la inspección se evidenció exceso de polvo y suciedad acumulada en el ventilador y en la placa del equipo, lo cual puede afectar la correcta disipación de calor y el funcionamiento adecuado de los componentes electrónicos. | U6: Como parte del mantenimiento, se realizó limpieza externa e interna del equipo, incluyendo la limpieza de las placas de circuito con limpiacontactos. Asimismo, se efectuó la limpieza de bornes, conectores, panel frontal y pantallas. Adicionalmente, se llevó a cabo la revisión y ajuste de perillas de control, inspección del cable de alimentación, verificación de interruptores y evaluación del sistema de ventilación, garantizando el correcto funcionamiento del equipo. | V6: Operativo | Y6: Finalizada | AA6: Tecnico
A7: S-04 | B7: Juan Camilo Cañas | C7: 1005205581 | D7: MIP | E7: 46088 | F7: 0.54166667 | G7: fuentes DC | H7: PEAKTECH | I7: 410326 | K7: Electrónica A 603 | L7: NA | N7: Se realizará MIP de limpieza interna y externa del equipo, de acuerdo con los tiempos establecidos en el cronograma de mantenimiento. Esta intervención se lleva a cabo con el fin de prevenir fallas asociadas a la acumulación de polvo, suciedad y posibles falsos contactos, los cuales pueden afectar el desempeño, la seguridad y la vida útil del equipo. | P7: Juan Camilo Cañas | Q7: 46088 | R7: Contratistas laboratorios de IEE | S7: N.A | T7: Durante la inspección se evidenció exceso de polvo y suciedad acumulada en el ventilador y en la placa del equipo, lo cual puede afectar la correcta disipación de calor y el funcionamiento adecuado de los componentes electrónicos. | U7: Como parte del mantenimiento, se realizó limpieza externa e interna del equipo, incluyendo la limpieza de las placas de circuito con limpiacontactos. Asimismo, se efectuó la limpieza de bornes, conectores, panel frontal y pantallas. Adicionalmente, se llevó a cabo la revisión y ajuste de perillas de control, inspección del cable de alimentación, verificación de interruptores y evaluación del sistema de ventilación, garantizando el correcto funcionamiento del equipo. | V7: Operativo | Y7: Finalizada | AA7: Tecnico
A8: S-05 | B8: Juan Camilo Cañas | C8: 1005205581 | D8: MIP | E8: 46088 | F8: 0.58333333 | G8: fuentes DC | H8: PEAKTECH | I8: 410325 | K8: Electrónica A 603 | L8: NA | N8: Se realizará MIP de limpieza interna y externa del equipo, de acuerdo con los tiempos establecidos en el cronograma de mantenimiento. Esta intervención se lleva a cabo con el fin de prevenir fallas asociadas a la acumulación de polvo, suciedad y posibles falsos contactos, los cuales pueden afectar el desempeño, la seguridad y la vida útil del equipo. | P8: Juan Camilo Cañas | Q8: 46088 | R8: Contratistas laboratorios de IEE | S8: N.A | T8: Durante la inspección se evidenció exceso de polvo y suciedad acumulada en el ventilador y en la placa del equipo, lo cual puede afectar la correcta disipación de calor y el funcionamiento adecuado de los componentes electrónicos. | U8: Como parte del mantenimiento, se realizó limpieza externa e interna del equipo, incluyendo la limpieza de las placas de circuito con limpiacontactos. Asimismo, se efectuó la limpieza de bornes, conectores, panel frontal y pantallas. Adicionalmente, se llevó a cabo la revisión y ajuste de perillas de control, inspección del cable de alimentación, verificación de interruptores y evaluación del sistema de ventilación, garantizando el correcto funcionamiento del equipo. | V8: Operativo | Y8: Finalizada | AA8: Tecnico
A9: S-06 | B9: Juan Camilo Cañas | C9: 1005205581 | D9: MIP | E9: 46097 | F9: 0.41666667 | G9: Generador de señales | H9: RIGOL | I9: 410276 | K9: Electrónica A 603 | L9: NA | N9: Se realizará MIP de limpieza interna y externa del equipo, de acuerdo con los tiempos establecidos en el cronograma de mantenimiento. Esta intervención se lleva a cabo con el fin de prevenir fallas asociadas a la acumulación de polvo, suciedad y posibles falsos contactos, los cuales pueden afectar el desempeño, la seguridad y la vida útil del equipo. | P9: Juan Camilo Cañas | Q9: 46097 | R9: Contratistas laboratorios de IEE | S9: N.A | T9: Durante la inspección se evidenció exceso de polvo y suciedad acumulada en el ventilador y en la placa del equipo, lo cual puede afectar la correcta disipación de calor y el funcionamiento adecuado de los componentes electrónicos. | U9: Como parte del mantenimiento, se realizó limpieza externa e interna del equipo, incluyendo panel frontal, pantallas, teclas de control y conectores de salida (BNC). También se efectuó la inspección del cable de alimentación y enchufe, la revisión del estado y funcionamiento de perillas y botones de ajuste, así como la verificación del sistema de ventilación y disipación térmica, con el fin de asegurar un funcionamiento adecuado y confiable del equipo. | V9: Operativo | Y9: Finalizada | AA9: Tecnico
A10: S-07 | B10: Juan Camilo Cañas | C10: 1005205581 | D10: MIP | E10: 46097 | F10: 0.45833333 | G10: Generador de señales | H10: RIGOL | I10: 410287 | K10: Electrónica A 603 | L10: NA | N10: Se realizará MIP de limpieza interna y externa del equipo, de acuerdo con los tiempos establecidos en el cronograma de mantenimiento. Esta intervención se lleva a cabo con el fin de prevenir fallas asociadas a la acumulación de polvo, suciedad y posibles falsos contactos, los cuales pueden afectar el desempeño, la seguridad y la vida útil del equipo. | P10: Juan Camilo Cañas | Q10: 46097 | R10: Contratistas laboratorios de IEE | S10: N.A | T10: Durante la inspección se evidenció exceso de polvo y suciedad acumulada en el ventilador y en la placa del equipo, lo cual puede afectar la correcta disipación de calor y el funcionamiento adecuado de los componentes electrónicos. | U10: Como parte del mantenimiento, se realizó limpieza externa e interna del equipo, incluyendo panel frontal, pantallas, teclas de control y conectores de salida (BNC). También se efectuó la inspección del cable de alimentación y enchufe, la revisión del estado y funcionamiento de perillas y botones de ajuste, así como la verificación del sistema de ventilación y disipación térmica, con el fin de asegurar un funcionamiento adecuado y confiable del equipo. | V10: Operativo | Y10: Finalizada | AA10: Tecnico
A11: S-08 | B11: Juan Felipe Bonilla Albaron | C11: 20232005180 | D11: MIC | E11: 46078 | F11: 0 | G11: multimetro | H11: ERASMUS | I11: 27 | K11: MAQUINAS B | L11: MOTORES | M11: 27 | N11: Daño en la bocina | P11: Juan Camilo Cañas | Q11: 46106 | R11: Contratistas laboratorios de IEE | S11: N.A | T11: Buzzer del multimetro haciendo interferencia por soldadura desprendida | U11: se procede a rectificar la soldadura | V11: Operativo | Y11: Finalizada | AA11: Tecnico
A12: S-09 | B12: KAROL ESTEFANIA AGUILAR PALACIOS | C12: 20221007091 | D12: MIC | E12: 46111 | F12: 0.5 | G12: FUENTE DC | H12: PEAKTECH | I12: 410312 | J12: 15 | K12: MAQUINAS A | L12: CONVERSION ELECTROMAGNETICA | M12: 4 | N12: LA FUENTE TIENE EL PULSADOR DONDE SE REALIZAN CAMBIOS DE SERIE, PARALELO, DAÑADO, SE QUEDA PEGADO EL PULSADOR | P12: VANESSA CADENA | Q12: 46112 | R12: Contratistas laboratorios de IEE | S12: N.A | T12: SE EVIDENCIA QUE EL PULSADOR PARA PARALELO/SERIE SE QUEDA ATASCADO UNA VEZ SE PULSA | U12: SE REALIZA EL CAMBIO DEL PULSADOR POR UNO QUE ESTA EN LOS EQUIPOS PARA DAR DE BAJA | V12: Operativo | Y12: Finalizada | AA12: Tecnico
A13: S-10 | B13: Juan Camilo Cañas | C13: 1005205581 | D13: MIP | E13: 46112 | F13: 0.34375 | G13: Generador de señales | H13: RIGOL | I13: 410289 | K13: Electrónica A 603 | L13: NA | N13: Se realizará MIP de limpieza interna y externa del equipo, de acuerdo con los tiempos establecidos en el cronograma de mantenimiento. Esta intervención se lleva a cabo con el fin de prevenir fallas asociadas a la acumulación de polvo, suciedad y posibles falsos contactos, los cuales pueden afectar el desempeño, la seguridad y la vida útil del equipo. | P13: Juan Camilo Cañas | Q13: 46112 | R13: Contratistas laboratorios de IEE | S13: N.A | T13: Durante la inspección se evidenció exceso de polvo y suciedad acumulada en el ventilador y en la placa del equipo, lo cual puede afectar la correcta disipación de calor y el funcionamiento adecuado de los componentes electrónicos. | U13: Como parte del mantenimiento, se realizó limpieza externa e interna del equipo, incluyendo panel frontal, pantallas, teclas de control y conectores de salida (BNC). También se efectuó la inspección del cable de alimentación y enchufe, la revisión del estado y funcionamiento de perillas y botones de ajuste, así como la verificación del sistema de ventilación y disipación térmica, con el fin de asegurar un funcionamiento adecuado y confiable del equipo. | V13: Operativo | Y13: Finalizada | AA13: Tecnico
A14: S-11 | B14: Juan Camilo Cañas | C14: 1005205581 | D14: MIP | E14: 46112 | F14: 0.39583333 | G14: Generador de señales | H14: RIGOL | I14: 410291 | K14: Electrónica A 603 | L14: NA | N14: Se realizará MIP de limpieza interna y externa del equipo, de acuerdo con los tiempos establecidos en el cronograma de mantenimiento. Esta intervención se lleva a cabo con el fin de prevenir fallas asociadas a la acumulación de polvo, suciedad y posibles falsos contactos, los cuales pueden afectar el desempeño, la seguridad y la vida útil del equipo. | P14: Juan Camilo Cañas | Q14: 46112 | R14: Contratistas laboratorios de IEE | S14: N.A | T14: Durante la inspección se evidenció exceso de polvo y suciedad acumulada en el ventilador y en la placa del equipo, lo cual puede afectar la correcta disipación de calor y el funcionamiento adecuado de los componentes electrónicos. | U14: Como parte del mantenimiento, se realizó limpieza externa e interna del equipo, incluyendo panel frontal, pantallas, teclas de control y conectores de salida (BNC). También se efectuó la inspección del cable de alimentación y enchufe, la revisión del estado y funcionamiento de perillas y botones de ajuste, así como la verificación del sistema de ventilación y disipación térmica, con el fin de asegurar un funcionamiento adecuado y confiable del equipo. | V14: Operativo | Y14: Finalizada | AA14: Tecnico
A15: S-12 | B15: Juan Camilo Cañas | C15: 1005205581 | D15: MIP | E15: 46112 | F15: 0.44791667 | G15: Generador de señales | H15: RIGOL | I15: 410292 | K15: Electrónica A 603 | L15: NA | N15: Se realizará MIP de limpieza interna y externa del equipo, de acuerdo con los tiempos establecidos en el cronograma de mantenimiento. Esta intervención se lleva a cabo con el fin de prevenir fallas asociadas a la acumulación de polvo, suciedad y posibles falsos contactos, los cuales pueden afectar el desempeño, la seguridad y la vida útil del equipo. | P15: Juan Camilo Cañas | Q15: 46112 | R15: Contratistas laboratorios de IEE | S15: N.A | T15: Durante la inspección se evidenció exceso de polvo y suciedad acumulada en el ventilador y en la placa del equipo, lo cual puede afectar la correcta disipación de calor y el funcionamiento adecuado de los componentes electrónicos. | U15: Como parte del mantenimiento, se realizó limpieza externa e interna del equipo, incluyendo panel frontal, pantallas, teclas de control y conectores de salida (BNC). También se efectuó la inspección del cable de alimentación y enchufe, la revisión del estado y funcionamiento de perillas y botones de ajuste, así como la verificación del sistema de ventilación y disipación térmica, con el fin de asegurar un funcionamiento adecuado y confiable del equipo. | V15: Operativo | Y15: Finalizada | AA15: Tecnico
A16: S-13 | B16: Juan Camilo Cañas | C16: 1005205581 | D16: MIP | E16: 46112 | F16: 0.5 | G16: Generador de señales | H16: RIGOL | I16: 410273 | K16: Electrónica A 603 | L16: NA | N16: Se realizará MIP de limpieza interna y externa del equipo, de acuerdo con los tiempos establecidos en el cronograma de mantenimiento. Esta intervención se lleva a cabo con el fin de prevenir fallas asociadas a la acumulación de polvo, suciedad y posibles falsos contactos, los cuales pueden afectar el desempeño, la seguridad y la vida útil del equipo. | P16: Juan Camilo Cañas | Q16: 46112 | R16: Contratistas laboratorios de IEE | S16: N.A | T16: Durante la inspección se evidenció exceso de polvo y suciedad acumulada en el ventilador y en la placa del equipo, lo cual puede afectar la correcta disipación de calor y el funcionamiento adecuado de los componentes electrónicos. | U16: Como parte del mantenimiento, se realizó limpieza externa e interna del equipo, incluyendo panel frontal, pantallas, teclas de control y conectores de salida (BNC). También se efectuó la inspección del cable de alimentación y enchufe, la revisión del estado y funcionamiento de perillas y botones de ajuste, así como la verificación del sistema de ventilación y disipación térmica, con el fin de asegurar un funcionamiento adecuado y confiable del equipo. | V16: Operativo | Y16: Finalizada | AA16: Tecnico
A17: S-14 | B17: Juan Camilo Cañas | C17: 1005205581 | D17: MIP | E17: 46118 | F17: 0.425 | G17: Fuente Dc | H17: PEAKTECH | I17: 410327 | K17: Electrónica B 604 | L17: NA | N17: Se realizará MIP de limpieza interna y externa del equipo, de acuerdo con los tiempos establecidos en el cronograma de mantenimiento. Esta intervención se lleva a cabo con el fin de prevenir fallas asociadas a la acumulación de polvo, suciedad y posibles falsos contactos, los cuales pueden afectar el desempeño, la seguridad y la vida útil del equipo. | P17: Juan Camilo Cañas | Q17: 46118 | R17: Contratistas laboratorios de IEE | S17: N.A | T17: Durante la inspección se evidenció exceso de polvo y suciedad acumulada en el ventilador y en la placa del equipo, lo cual puede afectar la correcta disipación de calor y el funcionamiento adecuado de los componentes electrónicos. | U17: Como parte del mantenimiento, se realizó limpieza externa e interna del equipo, incluyendo la limpieza de las placas de circuito con limpiacontactos. Asimismo, se efectuó la limpieza de bornes, conectores, panel frontal y pantallas. Adicionalmente, se llevó a cabo la revisión y ajuste de perillas de control, inspección del cable de alimentación, verificación de interruptores y evaluación del sistema de ventilación, garantizando el correcto funcionamiento del equipo. | V17: Operativo | Y17: Finalizada | AA17: Tecnico
A18: S-15 | B18: Juan Camilo Cañas | C18: 1005205581 | D18: MIP | E18: 46118 | F18: 0.46875 | G18: Fuente Dc | H18: PEAKTECH | I18: 110331 | K18: Electrónica B 604 | L18: NA | N18: Se realizará MIP de limpieza interna y externa del equipo, de acuerdo con los tiempos establecidos en el cronograma de mantenimiento. Esta intervención se lleva a cabo con el fin de prevenir fallas asociadas a la acumulación de polvo, suciedad y posibles falsos contactos, los cuales pueden afectar el desempeño, la seguridad y la vida útil del equipo. | P18: Juan Camilo Cañas | Q18: 46118 | R18: Contratistas laboratorios de IEE | S18: N.A | T18: Durante la inspección se evidenció exceso de polvo y suciedad acumulada en el ventilador y en la placa del equipo, lo cual puede afectar la correcta disipación de calor y el funcionamiento adecuado de los componentes electrónicos. | U18: Como parte del mantenimiento, se realizó limpieza externa e interna del equipo, incluyendo la limpieza de las placas de circuito con limpiacontactos. Asimismo, se efectuó la limpieza de bornes, conectores, panel frontal y pantallas. Adicionalmente, se llevó a cabo la revisión y ajuste de perillas de control, inspección del cable de alimentación, verificación de interruptores y evaluación del sistema de ventilación, garantizando el correcto funcionamiento del equipo. | V18: Operativo | Y18: Finalizada | AA18: Tecnico
A19: S-16 | B19: KAROL ESTEFANIA AGUILAR PALACIOS | C19: 20221007091 | D19: MIC | E19: 46120 | F19: 0.41666667 | G19: PINZA VATIMETRICA | H19: ERASMUS | I19: MBIH079931 | J19: 12 | K19: MAQUINAS A | L19: CIRCUITOS 2 | M19: ARMARIO 1 | N19: LA PINZA ESTA DESCALIBRADA | P19: VANESSA CADENA | Q19: 46120 | R19: Contratistas laboratorios de IEE | S19: N.A | T19: SE REALIZA LA VERIFICACION Y SE COMPARA CON DOS PINZAS MAS Y SE EVENCIA QUE NO ESTAN DANDO LOS MISMOS VALORES | U19: SE DESTAPA EL EQUIPO SIN EMBARGO NO SE EVIDENCIA NADA ANORMAL, POR LO QUE AL NO CONTAR CON LOS EQUIPOS NECESARIOS PARA LA CALIBRACION NO SE PUEDE HACER MAS | V19: Mantenimiento externo | Y19: Finalizada | AA19: Estudiante
A20: S-17 | B20: NICOLAS VELASQUEZ AMARILLO | C20: 20202005010 | D20: MIC | E20: 46121 | F20: 0.41666667 | G20: CARGA RESISTIVA TRIFASICA | H20: SOLINGENI | I20: 2020080300002 | J20: 3 | K20: MAQUINAS A | L20: TRANSFORMADORES | N20: AISLADORES QUEMADOS, CONECTORES ROTOS | P20: CARLOS RODRIGUEZ | Q20: 46121 | R20: Contratistas laboratorios de IEE | S20: N.A | T20: LOS AISLADORES INTERNOS DE LAS CARGAS ESTABAN AGRIETADOS Y ROTOS E IGUAL QUE LOS BORNES DE CONEXION | U20: SE SOLDAN LOS BORNES, SE AJUSTAN LOS AISLADORES Y SE CORRIGEN CON | V20: Operativo | Y20: Finalizada | AA20: Estudiante
A21: S-18 | B21: Juan Camilo Cañas | C21: 1005205581 | D21: MIP | E21: 46123 | F21: 0.34722222 | G21: Fuente Dc | H21: PEAKTECH | I21: 20250926005 | K21: Electrónica B 604 | L21: NA | N21: Se realizará MIP de limpieza interna y externa del equipo, de acuerdo con los tiempos establecidos en el cronograma de mantenimiento. Esta intervención se lleva a cabo con el fin de prevenir fallas asociadas a la acumulación de polvo, suciedad y posibles falsos contactos, los cuales pueden afectar el desempeño, la seguridad y la vida útil del equipo. | P21: Juan Camilo Cañas | Q21: 46123 | R21: Contratistas laboratorios de IEE | S21: N.A | T21: Durante la inspección se evidenció exceso de polvo y suciedad acumulada en el ventilador y en la placa del equipo, lo cual puede afectar la correcta disipación de calor y el funcionamiento adecuado de los componentes electrónicos. | U21: Como parte del mantenimiento, se realizó limpieza externa e interna del equipo, incluyendo la limpieza de las placas de circuito con limpiacontactos. Asimismo, se efectuó la limpieza de bornes, conectores, panel frontal y pantallas. Adicionalmente, se llevó a cabo la revisión y ajuste de perillas de control, inspección del cable de alimentación, verificación de interruptores y evaluación del sistema de ventilación, garantizando el correcto funcionamiento del equipo. | V21: Operativo | Y21: Finalizada | AA21: Tecnico
A22: S-19 | B22: Juan Camilo Cañas | C22: 1005205581 | D22: MIP | E22: 46123 | F22: 0.38194444 | G22: Fuente Dc | H22: PEAKTECH | I22: 410331 | K22: Electrónica B 604 | L22: NA | N22: Se realizará MIP de limpieza interna y externa del equipo, de acuerdo con los tiempos establecidos en el cronograma de mantenimiento. Esta intervención se lleva a cabo con el fin de prevenir fallas asociadas a la acumulación de polvo, suciedad y posibles falsos contactos, los cuales pueden afectar el desempeño, la seguridad y la vida útil del equipo. | P22: Juan Camilo Cañas | Q22: 46123 | R22: Contratistas laboratorios de IEE | S22: N.A | T22: Durante la inspección se evidenció exceso de polvo y suciedad acumulada en el ventilador y en la placa del equipo, lo cual puede afectar la correcta disipación de calor y el funcionamiento adecuado de los componentes electrónicos. | U22: Como parte del mantenimiento, se realizó limpieza externa e interna del equipo, incluyendo la limpieza de las placas de circuito con limpiacontactos. Asimismo, se efectuó la limpieza de bornes, conectores, panel frontal y pantallas. Adicionalmente, se llevó a cabo la revisión y ajuste de perillas de control, inspección del cable de alimentación, verificación de interruptores y evaluación del sistema de ventilación, garantizando el correcto funcionamiento del equipo. | V22: Operativo | Y22: Finalizada | AA22: Tecnico
A23: S-20 | B23: Juan Camilo Cañas | C23: 1005205581 | D23: MIP | E23: 46123 | F23: 0.45138889 | G23: Fuente Dc | H23: PEAKTECH | I23: 410330 | K23: Electrónica B 604 | L23: NA | N23: Se realizará MIP de limpieza interna y externa del equipo, de acuerdo con los tiempos establecidos en el cronograma de mantenimiento. Esta intervención se lleva a cabo con el fin de prevenir fallas asociadas a la acumulación de polvo, suciedad y posibles falsos contactos, los cuales pueden afectar el desempeño, la seguridad y la vida útil del equipo. | P23: Juan Camilo Cañas | Q23: 46123 | R23: Contratistas laboratorios de IEE | S23: N.A | T23: Durante la inspección se evidenció exceso de polvo y suciedad acumulada en el ventilador y en la placa del equipo, lo cual puede afectar la correcta disipación de calor y el funcionamiento adecuado de los componentes electrónicos. | U23: Como parte del mantenimiento, se realizó limpieza externa e interna del equipo, incluyendo la limpieza de las placas de circuito con limpiacontactos. Asimismo, se efectuó la limpieza de bornes, conectores, panel frontal y pantallas. Adicionalmente, se llevó a cabo la revisión y ajuste de perillas de control, inspección del cable de alimentación, verificación de interruptores y evaluación del sistema de ventilación, garantizando el correcto funcionamiento del equipo. | V23: Operativo | Y23: Finalizada | AA23: Tecnico
A24: S-21 | B24: Juan Camilo Cañas | C24: 1005205581 | D24: MIP | E24: 46123 | F24: 0.48611111 | G24: Fuente Dc | H24: PEAKTECH | I24: 410315 | K24: Electrónica B 604 | L24: NA | N24: Se realizará MIP de limpieza interna y externa del equipo, de acuerdo con los tiempos establecidos en el cronograma de mantenimiento. Esta intervención se lleva a cabo con el fin de prevenir fallas asociadas a la acumulación de polvo, suciedad y posibles falsos contactos, los cuales pueden afectar el desempeño, la seguridad y la vida útil del equipo. | P24: Juan Camilo Cañas | Q24: 46123 | R24: Contratistas laboratorios de IEE | S24: N.A | T24: Durante la inspección se evidenció exceso de polvo y suciedad acumulada en el ventilador y en la placa del equipo, lo cual puede afectar la correcta disipación de calor y el funcionamiento adecuado de los componentes electrónicos. | U24: Como parte del mantenimiento, se realizó limpieza externa e interna del equipo, incluyendo la limpieza de las placas de circuito con limpiacontactos. Asimismo, se efectuó la limpieza de bornes, conectores, panel frontal y pantallas. Adicionalmente, se llevó a cabo la revisión y ajuste de perillas de control, inspección del cable de alimentación, verificación de interruptores y evaluación del sistema de ventilación, garantizando el correcto funcionamiento del equipo. | V24: Operativo | Y24: Finalizada | AA24: Tecnico
A25: S-22 | B25: Juan Camilo Cañas | C25: 1005205581 | D25: MIC | E25: 46111 | F25: 0.52222222 | G25: Fuente Dc | H25: PEAKTECH | I25: DS1AD105201432 | K25: Electrónica A 603 | L25: NA | N25: TIENE UN BOTON DAÑADO MECANICAMENTE (BOTON ENCENDIDO ) | P25: Juan Camilo Cañas | Q25: 46126 | R25: Contratistas laboratorios de IEE | S25: N.A | T25: EL MECANISMO DEL INTERRUPTOR DE ENCENDIDO FUFRIO DAÑO A NIVEL MECANICO | U25: Se procedio a cambiar el interruptor por uno extraido de un osciloscopio dañado | V25: Operativo | Y25: Finalizada | AA25: Tecnico
A26: S-23 | B26: DAVID SANTIAGO CASTELLANOS | C26: 20241007005 | D26: MIC | E26: 46106 | F26: 0.54166667 | G26: multimetro | H26: ERASMUS | I26: 9 | K26: CIRCUITOS A 607 | L26: CIRCUITOS 1 | M26: 9 | N26: PERILLA SELECTORA DEL MULTIMETRO DAÑADO | P26: Juan Camilo Cañas | Q26: 46126 | R26: Contratistas laboratorios de IEE | S26: N.A | U26: Cambio de perilla, se realiza el cambio con uno de los multimetros que se encunetran en proceso para dar de baja (79) | V26: Operativo | Y26: Finalizada | AA26: Tecnico
A27: S-24 | B27: CARLOS RODRIGUEZ | C27: 1003496413 | D27: MANTENIMIENTO | R27: Contratistas laboratorios de IEE | S27: N.A | Y27: Finalizada | AA27: Tecnico
A28: S-25 | B28: VANESSA CADENA | C28: 1001203428 | D28: MIP | E28: 46091 | F28: 0.33333333 | G28: FUENTE DC | H28: PEAKTECH | I28: 410320 | K28: MAQUINAS A | L28: NA | M28: 1 | N28: SE REALIZA LIMPIEZA Y CONEXION Y DESCONEXION DE COMPONENTES | R28: Contratistas laboratorios de IEE | S28: N.A | Y28: Finalizada | AA28: Tecnico
A29: S-26 | B29: VANESSA CADENA | C29: 1001203428 | D29: MIP | E29: 46092 | F29: 0.5 | G29: FUENTE DC | H29: PEAKTECH | I29: 90166417 | J29: 18 | K29: MAQUINAS A | L29: NA | M29: 2 | N29: SE REALIZA LIMPIEZA Y CONEXION Y DESCONEXION DE COMPONENTES | R29: Contratistas laboratorios de IEE | S29: N.A | Y29: Finalizada | AA29: Tecnico
A30: S-27 | B30: VANESSA CADENA | C30: 1001203428 | D30: MIP | E30: 46093 | F30: 0.33333333 | G30: FUENTE DC | H30: PEAKTECH | I30: 90166932 | J30: 75 | K30: MAQUINAS A | L30: NA | M30: 3 | N30: SE REALIZA LIMPIEZA Y CONEXION Y DESCONEXION DE COMPONENTES | R30: Contratistas laboratorios de IEE | S30: N.A | Y30: Finalizada | AA30: Tecnico
A31: S-28 | B31: VANESSA CADENA | C31: 1001203428 | D31: MIP | E31: 46094 | F31: 0.66666667 | G31: FUENTE DC | H31: PEAKTECH | I31: 410321 | J31: 6 | K31: MAQUINAS A | L31: NA | M31: 8 | N31: SE REALIZA LIMPIEZA Y CONEXION Y DESCONEXION DE COMPONENTES | R31: Contratistas laboratorios de IEE | S31: N.A | Y31: Finalizada | AA31: Tecnico
A32: S-29 | B32: VANESSA CADENA | C32: 1001203429 | D32: MIP | E32: 46097 | F32: 0.41666667 | G32: FUENTE DC | H32: PEAKTECH | I32: 20250926007 | J32: 20 | K32: MAQUINAS A | L32: NA | M32: 5 | N32: SE REALIZA LIMPIEZA Y CONEXION Y DESCONEXION DE COMPONENTES | R32: Contratistas laboratorios de IEE | S32: N.A | Y32: Finalizada | AA32: Tecnico
A33: S-30 | B33: VANESSA CADENA | C33: 1001203430 | D33: MIP | E33: 46098 | F33: 0.33333333 | G33: FUENTE DC | H33: PEAKTECH | I33: 410314 | J33: 89 | K33: MAQUINAS A | L33: NA | M33: 6 | N33: SE REALIZA LIMPIEZA Y CONEXION Y DESCONEXION DE COMPONENTES | R33: Contratistas laboratorios de IEE | S33: N.A | Y33: Finalizada | AA33: Tecnico
A34: S-31 | B34: VANESSA CADENA | C34: 1001203431 | D34: MIP | E34: 46099 | F34: 0.5 | G34: FUENTE DC | H34: PEAKTECH | I34: 410322 | K34: MAQUINAS A | L34: NA | M34: 7 | N34: SE REALIZA LIMPIEZA Y CONEXION Y DESCONEXION DE COMPONENTES | R34: Contratistas laboratorios de IEE | S34: N.A | Y34: Finalizada | AA34: Tecnico
A35: S-32 | B35: VANESSA CADENA | C35: 1001203432 | D35: MIP | E35: 46100 | F35: 0.33333333 | G35: FUENTE DC | H35: PEAKTECH | I35: 90166411 | J35: 2 | K35: MAQUINAS B | L35: NA | M35: 1 | N35: SE REALIZA LIMPIEZA Y CONEXION Y DESCONEXION DE COMPONENTES | R35: Contratistas laboratorios de IEE | S35: N.A | Y35: Finalizada | AA35: Tecnico
A36: S-33 | B36: VANESSA CADENA | C36: 1001203433 | D36: MIP | E36: 46101 | F36: 0.66666667 | G36: FUENTE DC | H36: PEAKTECH | I36: 90166986 | J36: 77 | K36: MAQUINAS B | L36: NA | M36: 2 | N36: SE REALIZA LIMPIEZA Y CONEXION Y DESCONEXION DE COMPONENTES | R36: Contratistas laboratorios de IEE | S36: N.A | Y36: Finalizada | AA36: Tecnico
A37: S-34 | B37: VANESSA CADENA | C37: 1001203435 | D37: MIP | E37: 46105 | F37: 0.33333333 | G37: FUENTE DC | H37: PEAKTECH | I37: 90166426 | J37: 72 | K37: MAQUINAS B | L37: NA | M37: 4 | N37: SE REALIZA LIMPIEZA Y CONEXION Y DESCONEXION DE COMPONENTES | R37: Contratistas laboratorios de IEE | S37: N.A | Y37: Finalizada | AA37: Tecnico
A38: S-35 | B38: VANESSA CADENA | C38: 1001203436 | D38: MIP | E38: 46106 | F38: 0.5 | G38: FUENTE DC | H38: PEAKTECH | I38: 90166399 | J38: 73 | K38: MAQUINAS B | L38: NA | M38: 5 | N38: SE REALIZA LIMPIEZA Y CONEXION Y DESCONEXION DE COMPONENTES | R38: Contratistas laboratorios de IEE | S38: N.A | Y38: Finalizada | AA38: Tecnico
A39: S-36 | B39: VANESSA CADENA | C39: 1001203437 | D39: MIP | E39: 46107 | F39: 0.33333333 | G39: FUENTE DC | H39: PEAKTECH | I39: 90166398 | J39: 3 | K39: MAQUINAS B | L39: NA | M39: 6 | N39: SE REALIZA LIMPIEZA Y CONEXION Y DESCONEXION DE COMPONENTES | R39: Contratistas laboratorios de IEE | S39: N.A | Y39: Finalizada | AA39: Tecnico
A40: S-37 | B40: VANESSA CADENA | C40: 1001203438 | D40: MIP | E40: 46108 | F40: 0.66666667 | G40: FUENTE DC | H40: PEAKTECH | I40: 90166948 | J40: 28 | K40: MAQUINAS B | L40: NA | M40: 7 | N40: SE REALIZA LIMPIEZA Y CONEXION Y DESCONEXION DE COMPONENTES | R40: Contratistas laboratorios de IEE | S40: N.A | Y40: Finalizada | AA40: Tecnico
...

Sheet CPS
A1: Nombres | B1: Cedula
A2: CARLOS RODRIGUEZ | B2: 1 | C2: ASISTENCIAL
A3: NELSON GRANADOS | B3: 2 | C3: PLANTA ASISTENCIAL
A4: Juan Camilo Cañas | B4: 3 | C4: Técnico
A5: VANESSA CADENA | B5: 4 | C5: TECNICO
B6: 5
B7: 6
B8: 7

Sheet REPORTE DE MANTENIMIENTO
C2: REPORTE DE MANTENIMIENTO | H2: Código: GL-PR-002-FR-011
C3: Macro proceso: Apoyo a los misional | H3: Versión: 01
C4: Proceso: Gestión de Laboratorios | H4: Fecha de aprobación: 23/05/2018
B7: Nombre de solicitante | C7: =VLOOKUP($C$13,Datos!A4:U663,2,FALSE) | F7: Código | G7: =VLOOKUP($C$13,Datos!A4:U663,3,FALSE) | I7: Marca | J7: =VLOOKUP($C$13,Datos!A4:U663,8,FALSE)
B8: Tipo de solicitante | C8: =VLOOKUP($C$13,Datos!A4:U663,4,FALSE) | F8: Fecha | G8: =VLOOKUP($C$13,Datos!A4:U663,5,FALSE) | I8: Placa | J8: =VLOOKUP($C$13,Datos!A4:U663,9,FALSE)
B9: Nombre del equipo | C9: =VLOOKUP(C13,OfficeForms.Table[#All],7,FALSE) | F9: Hora | G9: =VLOOKUP($C$13,Datos!A4:Z187,6,FALSE) | I9: Número | J9: =VLOOKUP($C$13,Datos!A4:U663,10,FALSE)
B10: Asignatura | C10: =VLOOKUP(C13,OfficeForms.Table[#All],12,FALSE) | F10: Sala de ubicación | G10: =VLOOKUP($C$13,Datos!A4:U663,11,FALSE) | I10: Banco | J10: =VLOOKUP($C$13,Datos!A4:U663,13,FALSE)
B11: Descripción del daño | C11: =VLOOKUP($C$13,Datos!A4:U663,14,FALSE) | G11: Observación | H11: =VLOOKUP($C$13,Datos!A4:U663,15,FALSE)
B12: DETALLES DEL MANTENIMIENTO
B13: CONSECUTIVO | C13: 2 | G13: Fecha de entrada | H13: =G8 | I13: Fecha de realización | J13: =VLOOKUP($C$13,Datos!A4:Z187,17,FALSE)
B14: Técnico que realiza | C14: =VLOOKUP($C$13,Datos!A4:U663,16,FALSE)
B15: Diagnóstico | C15: =VLOOKUP($C$13,Datos!A4:U663,18,FALSE) | G15: Procedimiento | H15: =VLOOKUP($C$13,Datos!A4:U663,19,FALSE)
